Workbook

Sheet RETAIL SALES DATA.
A1: Order_ID | B1: Customer_Name | C1: Product_Name | D1: Product_Category | E1: Region | F1: Sales_Quantity | G1: Unit_Price | H1: Sales_Amount | I1: Cost | J1: Profit | K1: Order_Date | L1: Delivery_Date | M1: Employee_Name | N1: Customer_Rating | O1: Login_Time | P1: Working_Hours | Q1: Orders | R1: HIGH VALUE/LOW | S1: P/L | T1: CUSTOMER NAME | U1: PRUDUCT | V1: YEAR | W1: MONTH | X1: DAY | Y1: MONTH2 | Z1: DELIVERY DATE
A2: ORD0001 | B2: Michael Winters | C2: Pen | D2: Office Supplies | E2: South | F2: 4 | G2: 1578.68 | H2: 6314.72 | I2: 4409.14 | J2: 1905.58 | K2: 45913 | L2: 45922 | M2: Rahul | N2: 5 | O2: 10:12:00 | P2: 8.9 | Q2: =RIGHT(A2,"4") -> 0001 | R2: =IF('RETAIL SALES DATA.'!H2>AVERAGE('RETAIL SALES DATA.'!H2:H1001),"HIGHEST VALUE","LOWEST VALUE") -> LOWEST VALUE | S2: =IF(J2>0,"Profit","Loss") -> Profit | T2: =PROPER(B2) -> Michael Winters | U2: =PROPER(C2) -> Pen | V2: =YEAR(K2) -> 2025 | W2: =MONTH(L2) -> 9 | X2: =DAY(K2) -> 13 | Y2: =TEXT(K2,"MMM") -> Sep | Z2: =L2-K2 -> 9
A3: ORD0002 | B3: James Olson | C3: Pen | D3: Office Supplies | E3: North | F3: 18 | G3: 1427.85 | H3: 25701.3 | I3: 15663.81 | J3: 10037.49 | K3: 46023 | L3: 46026 | M3: Megha | N3: 1 | O3: 08:15:00 | P3: 8.6 | Q3: =RIGHT(A3,"4") -> 0002 | R3: =IF('RETAIL SALES DATA.'!H3>AVERAGE('RETAIL SALES DATA.'!H3:H1002),"HIGHEST VALUE","LOWEST VALUE") -> LOWEST VALUE | S3: =IF(J3>0,"Profit","Loss") -> Profit | T3: =PROPER(B3) -> James Olson | U3: =PROPER(C3) -> Pen | V3: =YEAR(K3) -> 2026 | W3: =MONTH(L3) -> 1 | X3: =DAY(K3) -> 1 | Y3: =TEXT(K3,"MMM") -> Jan | Z3: =L3-K3 -> 3
A4: ORD0003 | B4: Brittney Simmons | C4: Desk | D4: Furniture | E4: West | F4: 18 | G4: 3667.53 | H4: 66015.54 | I4: 41337.25 | J4: 24678.29 | K4: 46152 | L4: 46161 | M4: Arun | N4: 5 | O4: 11:33:00 | P4: 7.3 | Q4: =RIGHT(A4,"4") -> 0003 | R4: =IF('RETAIL SALES DATA.'!H4>AVERAGE('RETAIL SALES DATA.'!H4:H1003),"HIGHEST VALUE","LOWEST VALUE") -> HIGHEST VALUE | S4: =IF(J4>0,"Profit","Loss") -> Profit | T4: =PROPER(B4) -> Brittney Simmons | U4: =PROPER(C4) -> Desk | V4: =YEAR(K4) -> 2026 | W4: =MONTH(L4) -> 5 | X4: =DAY(K4) -> 10 | Y4: =TEXT(K4,"MMM") -> May | Z4: =L4-K4 -> 9
A5: ORD0004 | B5: Courtney Park | C5: Marker | D5: Office Supplies | E5: North | F5: 1 | G5: 3550.31 | H5: 3550.31 | I5: 2061.79 | J5: 1488.52 | K5: 45483 | L5: 45491 | M5: Vivek | N5: 4 | O5: 11:19:00 | P5: 6.5 | Q5: =RIGHT(A5,"4") -> 0004 | R5: =IF('RETAIL SALES DATA.'!H5>AVERAGE('RETAIL SALES DATA.'!H5:H1004),"HIGHEST VALUE","LOWEST VALUE") -> LOWEST VALUE | S5: =IF(J5>0,"Profit","Loss") -> Profit | T5: =PROPER(B5) -> Courtney Park | U5: =PROPER(C5) -> Marker | V5: =YEAR(K5) -> 2024 | W5: =MONTH(L5) -> 7 | X5: =DAY(K5) -> 10 | Y5: =TEXT(K5,"MMM") -> Jul | Z5: =L5-K5 -> 8
A6: ORD0005 | B6: Chloe Villa | C6: Laptop | D6: Electronics | E6: East | F6: 13 | G6: 1838.36 | H6: 23898.68 | I6: 17283.83 | J6: 6614.85 | K6: 46052 | L6: 46062 | M6: Diya | N6: 1 | O6: 10:02:00 | P6: 8.7 | Q6: =RIGHT(A6,"4") -> 0005 | R6: =IF('RETAIL SALES DATA.'!H6>AVERAGE('RETAIL SALES DATA.'!H6:H1005),"HIGHEST VALUE","LOWEST VALUE") -> LOWEST VALUE | S6: =IF(J6>0,"Profit","Loss") -> Profit | T6: =PROPER(B6) -> Chloe Villa | U6: =PROPER(C6) -> Laptop | V6: =YEAR(K6) -> 2026 | W6: =MONTH(L6) -> 2 | X6: =DAY(K6) -> 30 | Y6: =TEXT(K6,"MMM") -> Jan | Z6: =L6-K6 -> 10
A7: ORD0006 | B7: Erin Ross | C7: Mouse | D7: Electronics | E7: West | F7: 1 | G7: 4093.77 | H7: 4093.77 | I7: 2721.22 | J7: 1372.55 | K7: 45502 | L7: 45505 | M7: Fathima | N7: 1 | O7: 09:28:00 | P7: 8.6 | Q7: =RIGHT(A7,"4") -> 0006 | R7: =IF('RETAIL SALES DATA.'!H7>AVERAGE('RETAIL SALES DATA.'!H7:H1006),"HIGHEST VALUE","LOWEST VALUE") -> LOWEST VALUE | S7: =IF(J7>0,"Profit","Loss") -> Profit | T7: =PROPER(B7) -> Erin Ross | U7: =PROPER(C7) -> Mouse | V7: =YEAR(K7) -> 2024 | W7: =MONTH(L7) -> 8 | X7: =DAY(K7) -> 29 | Y7: =TEXT(K7,"MMM") -> Jul | Z7: =L7-K7 -> 3
A8: ORD0007 | B8: Ryan Brown | C8: Laptop | D8: Electronics | E8: West | F8: 17 | G8: 2540.86 | H8: 43194.62 | I8: 22584.56 | J8: 20610.06 | K8: 45494 | L8: 45498 | M8: Rahul | N8: 1 | O8: 08:18:00 | P8: 8.9 | Q8: =RIGHT(A8,"4") -> 0007 | R8: =IF('RETAIL SALES DATA.'!H8>AVERAGE('RETAIL SALES DATA.'!H8:H1007),"HIGHEST VALUE","LOWEST VALUE") -> HIGHEST VALUE | S8: =IF(J8>0,"Profit","Loss") -> Profit | T8: =PROPER(B8) -> Ryan Brown | U8: =PROPER(C8) -> Laptop | V8: =YEAR(K8) -> 2024 | W8: =MONTH(L8) -> 7 | X8: =DAY(K8) -> 21 | Y8: =TEXT(K8,"MMM") -> Jul | Z8: =L8-K8 -> 4
A9: ORD0008 | B9: Keith Winters | C9: Notebook | D9: Office Supplies | E9: East | F9: 12 | G9: 4957.92 | H9: 59495.04 | I9: 49409.66 | J9: 10085.38 | K9: 46147 | L9: 46150 | M9: Sneha | N9: 2 | O9: 09:04:00 | P9: 8 | Q9: =RIGHT(A9,"4") -> 0008 | R9: =IF('RETAIL SALES DATA.'!H9>AVERAGE('RETAIL SALES DATA.'!H9:H1008),"HIGHEST VALUE","LOWEST VALUE") -> HIGHEST VALUE | S9: =IF(J9>0,"Profit","Loss") -> Profit | T9: =PROPER(B9) -> Keith Winters | U9: =PROPER(C9) -> Notebook | V9: =YEAR(K9) -> 2026 | W9: =MONTH(L9) -> 5 | X9: =DAY(K9) -> 5 | Y9: =TEXT(K9,"MMM") -> May | Z9: =L9-K9 -> 3
A10: ORD0009 | B10: Richard Payne | C10: Table | D10: Furniture | E10: East | F10: 2 | G10: 3280.82 | H10: 6561.64 | I10: 5871.1 | J10: 690.54 | K10: 45607 | L10: 45610 | M10: Vivek | N10: 1 | O10: 11:17:00 | P10: 6.6 | Q10: =RIGHT(A10,"4") -> 0009 | R10: =IF('RETAIL SALES DATA.'!H10>AVERAGE('RETAIL SALES DATA.'!H10:H1009),"HIGHEST VALUE","LOWEST VALUE") -> LOWEST VALUE | S10: =IF(J10>0,"Profit","Loss") -> Profit | T10: =PROPER(B10) -> Richard Payne | U10: =PROPER(C10) -> Table | V10: =YEAR(K10) -> 2024 | W10: =MONTH(L10) -> 11 | X10: =DAY(K10) -> 11 | Y10: =TEXT(K10,"MMM") -> Nov | Z10: =L10-K10 -> 3
A11: ORD0010 | B11: Cory Roberson | C11: Pen | D11: Office Supplies | E11: North | F11: 14 | G11: 1988.47 | H11: 27838.58 | I11: 19080.73 | J11: 8757.85 | K11: 45712 | L11: 45716 | M11: Rahul | N11: 2 | O11: 11:14:00 | P11: 9.4 | Q11: =RIGHT(A11,"4") -> 0010 | R11: =IF('RETAIL SALES DATA.'!H11>AVERAGE('RETAIL SALES DATA.'!H11:H1010),"HIGHEST VALUE","LOWEST VALUE") -> HIGHEST VALUE | S11: =IF(J11>0,"Profit","Loss") -> Profit | T11: =PROPER(B11) -> Cory Roberson | U11: =PROPER(C11) -> Pen | V11: =YEAR(K11) -> 2025 | W11: =MONTH(L11) -> 2 | X11: =DAY(K11) -> 24 | Y11: =TEXT(K11,"MMM") -> Feb | Z11: =L11-K11 -> 4 | AB11: MONTH | AC11: 2025 | AD11: 2024 | AE11: 2026
A12: ORD0011 | B12: Amanda Cox | C12: Desk | D12: Furniture | E12: North | F12: 15 | G12: 991.66 | H12: 14874.9 | I12: 11249.49 | J12: 3625.41 | K12: 45628 | L12: 45634 | M12: Akhil | N12: 5 | O12: 11:14:00 | P12: 9.5 | Q12: =RIGHT(A12,"4") -> 0011 | R12: =IF('RETAIL SALES DATA.'!H12>AVERAGE('RETAIL SALES DATA.'!H12:H1011),"HIGHEST VALUE","LOWEST VALUE") -> LOWEST VALUE | S12: =IF(J12>0,"Profit","Loss") -> Profit | T12: =PROPER(B12) -> Amanda Cox | U12: =PROPER(C12) -> Desk | V12: =YEAR(K12) -> 2024 | W12: =MONTH(L12) -> 12 | X12: =DAY(K12) -> 2 | Y12: =TEXT(K12,"MMM") -> Dec | Z12: =L12-K12 -> 6 | AB12: Jan | AC12: =SUMIFS($H$2:$H$1001,$Y$2:$Y$1001,AB12,$V$2:$V$1001,V986) -> 931394.12 | AD12: =SUMIFS($H$2:$H$1001,$Y$2:$Y$1001,AB12,$V$2:$V$1001,V990) -> 0 | AE12: =SUMIFS($H$2:$H$1001,$Y$2:$Y$1001,AB12,$V$2:$V$1001,V3) -> 1122389.7
A13: ORD0012 | B13: Joseph Allison | C13: Chair | D13: Furniture | E13: South | F13: 12 | G13: 4247.3 | H13: 50967.6 | I13: 39899.98 | J13: 11067.62 | K13: 45786 | L13: 45795 | M13: Sneha | N13: 3 | O13: 11:34:00 | P13: 6.8 | Q13: =RIGHT(A13,"4") -> 0012 | R13: =IF('RETAIL SALES DATA.'!H13>AVERAGE('RETAIL SALES DATA.'!H13:H1012),"HIGHEST VALUE","LOWEST VALUE") -> HIGHEST VALUE | S13: =IF(J13>0,"Profit","Loss") -> Profit | T13: =PROPER(B13) -> Joseph Allison | U13: =PROPER(C13) -> Chair | V13: =YEAR(K13) -> 2025 | W13: =MONTH(L13) -> 5 | X13: =DAY(K13) -> 9 | Y13: =TEXT(K13,"MMM") -> May | Z13: =L13-K13 -> 9 | AB13: Feb | AC13: =SUMIFS($H$2:$H$1001,$Y$2:$Y$1001,AB13,$V$2:$V$1001,V987) -> 1188601.5 | AD13: =SUMIFS($H$2:$H$1001,$Y$2:$Y$1001,AB13,$V$2:$V$1001,V991) -> 0 | AE13: =SUMIFS($H$2:$H$1001,$Y$2:$Y$1001,AB13,$V$2:$V$1001,V4) -> 855184.88
A14: ORD0013 | B14: Sarah Hernandez | C14: Desk | D14: Furniture | E14: East | F14: 10 | G14: 761.02 | H14: 7610.2 | I14: 4990.85 | J14: 2619.35 | K14: 45812 | L14: 45817 | M14: Rahul | N14: 1 | O14: 09:38:00 | P14: 8.1 | Q14: =RIGHT(A14,"4") -> 0013 | R14: =IF('RETAIL SALES DATA.'!H14>AVERAGE('RETAIL SALES DATA.'!H14:H1013),"HIGHEST VALUE","LOWEST VALUE") -> LOWEST VALUE | S14: =IF(J14>0,"Profit","Loss") -> Profit | T14: =PROPER(B14) -> Sarah Hernandez | U14: =PROPER(C14) -> Desk | V14: =YEAR(K14) -> 2025 | W14: =MONTH(L14) -> 6 | X14: =DAY(K14) -> 4 | Y14: =TEXT(K14,"MMM") -> Jun | Z14: =L14-K14 -> 5 | AB14: Mar | AC14: =SUMIFS($H$2:$H$1001,$Y$2:$Y$1001,AB14,$V$2:$V$1001,V988) -> 1343369.7 | AD14: =SUMIFS($H$2:$H$1001,$Y$2:$Y$1001,AB14,$V$2:$V$1001,V992) -> 1343369.7 | AE14: =SUMIFS($H$2:$H$1001,$Y$2:$Y$1001,AB14,$V$2:$V$1001,V5) -> 0 | AI14: YEAR
A15: ORD0014 | B15: John Dixon | C15: Laptop | D15: Electronics | E15: West | F15: 4 | G15: 2151.7 | H15: 8606.8 | I15: 7408.45 | J15: 1198.35 | K15: 45747 | L15: 45754 | M15: Vivek | N15: 1 | O15: 10:16:00 | P15: 7.5 | Q15: =RIGHT(A15,"4") -> 0014 | R15: =IF('RETAIL SALES DATA.'!H15>AVERAGE('RETAIL SALES DATA.'!H15:H1014),"HIGHEST VALUE","LOWEST VALUE") -> LOWEST VALUE | S15: =IF(J15>0,"Profit","Loss") -> Profit | T15: =PROPER(B15) -> John Dixon | U15: =PROPER(C15) -> Laptop | V15: =YEAR(K15) -> 2025 | W15: =MONTH(L15) -> 4 | X15: =DAY(K15) -> 31 | Y15: =TEXT(K15,"MMM") -> Mar | Z15: =L15-K15 -> 7 | AB15: Apr | AC15: =SUMIFS($H$2:$H$1001,$Y$2:$Y$1001,AB15,$V$2:$V$1001,V989) -> 898947.59 | AD15: =SUMIFS($H$2:$H$1001,$Y$2:$Y$1001,AB15,$V$2:$V$1001,V993) -> 1380237 | AE15: =SUMIFS($H$2:$H$1001,$Y$2:$Y$1001,AB15,$V$2:$V$1001,V6) -> 898947.59 | AI15: 2024 | AJ15: =SUMIF($V$2:$V$1001,AI15,$H$2:$H$1001) -> 8340960.3
A16: ORD0015 | B16: Javier Cole | C16: Table | D16: Furniture | E16: South | F16: 1 | G16: 1909.53 | H16: 1909.53 | I16: 1574.6 | J16: 334.93 | K16: 45765 | L16: 45766 | M16: Megha | N16: 4 | O16: 09:13:00 | P16: 8.5 | Q16: =RIGHT(A16,"4") -> 0015 | R16: =IF('RETAIL SALES DATA.'!H16>AVERAGE('RETAIL SALES DATA.'!H16:H1015),"HIGHEST VALUE","LOWEST VALUE") -> LOWEST VALUE | S16: =IF(J16>0,"Profit","Loss") -> Profit | T16: =PROPER(B16) -> Javier Cole | U16: =PROPER(C16) -> Table | V16: =YEAR(K16) -> 2025 | W16: =MONTH(L16) -> 4 | X16: =DAY(K16) -> 18 | Y16: =TEXT(K16,"MMM") -> Apr | Z16: =L16-K16 -> 1 | AB16: May | AC16: =SUMIFS($H$2:$H$1001,$Y$2:$Y$1001,AB16,$V$2:$V$1001,V990) -> 530012.66 | AD16: =SUMIFS($H$2:$H$1001,$Y$2:$Y$1001,AB16,$V$2:$V$1001,V994) -> 1003309.7 | AE16: =SUMIFS($H$2:$H$1001,$Y$2:$Y$1001,AB16,$V$2:$V$1001,V7) -> 530012.66 | AI16: 2025 | AJ16: =SUMIF($V$2:$V$1001,AI16,$H$2:$H$1001) -> 13413606
A17: ORD0016 | B17: Nathan Kline | C17: Laptop | D17: Electronics | E17: West | F17: 13 | G17: 4687.55 | H17: 60938.15 | I17: 46078.82 | J17: 14859.33 | K17: 45880 | L17: 45883 | M17: Megha | N17: 4 | O17: 10:56:00 | P17: 7.1 | Q17: =RIGHT(A17,"4") -> 0016 | R17: =IF('RETAIL SALES DATA.'!H17>AVERAGE('RETAIL SALES DATA.'!H17:H1016),"HIGHEST VALUE","LOWEST VALUE") -> HIGHEST VALUE | S17: =IF(J17>0,"Profit","Loss") -> Profit | T17: =PROPER(B17) -> Nathan Kline | U17: =PROPER(C17) -> Laptop | V17: =YEAR(K17) -> 2025 | W17: =MONTH(L17) -> 8 | X17: =DAY(K17) -> 11 | Y17: =TEXT(K17,"MMM") -> Aug | Z17: =L17-K17 -> 3 | AB17: Jun | AC17: =SUMIFS($H$2:$H$1001,$Y$2:$Y$1001,AB17,$V$2:$V$1001,V991) -> 1180005.8 | AD17: =SUMIFS($H$2:$H$1001,$Y$2:$Y$1001,AB17,$V$2:$V$1001,V995) -> 0 | AE17: =SUMIFS($H$2:$H$1001,$Y$2:$Y$1001,AB17,$V$2:$V$1001,V8) -> 1180005.8 | AI17: 2026 | AJ17: =SUMIF($V$2:$V$1001,AI17,$H$2:$H$1001) -> 4716577.1
A18: ORD0017 | B18: Miss Christina Taylor | C18: Cupboard | D18: Furniture | E18: West | F18: 17 | G18: 4690.31 | H18: 79735.27 | I18: 45830.53 | J18: 33904.74 | K18: 46152 | L18: 46153 | M18: Fathima | N18: 5 | O18: 10:58:00 | P18: 7.7 | Q18: =RIGHT(A18,"4") -> 0017 | R18: =IF('RETAIL SALES DATA.'!H18>AVERAGE('RETAIL SALES DATA.'!H18:H1017),"HIGHEST VALUE","LOWEST VALUE") -> HIGHEST VALUE | S18: =IF(J18>0,"Profit","Loss") -> Profit | T18: =PROPER(B18) -> Miss Christina Taylor | U18: =PROPER(C18) -> Cupboard | V18: =YEAR(K18) -> 2026 | W18: =MONTH(L18) -> 5 | X18: =DAY(K18) -> 10 | Y18: =TEXT(K18,"MMM") -> May | Z18: =L18-K18 -> 1 | AB18: Jul | AC18: =SUMIFS($H$2:$H$1001,$Y$2:$Y$1001,AB18,$V$2:$V$1001,V992) -> 1051466.1 | AD18: =SUMIFS($H$2:$H$1001,$Y$2:$Y$1001,AB18,$V$2:$V$1001,V996) -> 1051466.1 | AE18: =SUMIFS($H$2:$H$1001,$Y$2:$Y$1001,AB18,$V$2:$V$1001,V9) -> 0
A19: ORD0018 | B19: Martin Morton | C19: Laptop | D19: Electronics | E19: North | F19: 19 | G19: 4107.4 | H19: 78040.6 | I19: 57454.36 | J19: 20586.24 | K19: 45814 | L19: 45817 | M19: Fathima | N19: 3 | O19: 09:20:00 | P19: 6 | Q19: =RIGHT(A19,"4") -> 0018 | R19: =IF('RETAIL SALES DATA.'!H19>AVERAGE('RETAIL SALES DATA.'!H19:H1018),"HIGHEST VALUE","LOWEST VALUE") -> HIGHEST VALUE | S19: =IF(J19>0,"Profit","Loss") -> Profit | T19: =PROPER(B19) -> Martin Morton | U19: =PROPER(C19) -> Laptop | V19: =YEAR(K19) -> 2025 | W19: =MONTH(L19) -> 6 | X19: =DAY(K19) -> 6 | Y19: =TEXT(K19,"MMM") -> Jun | Z19: =L19-K19 -> 3 | AB19: Aug | AC19: =SUMIFS($H$2:$H$1001,$Y$2:$Y$1001,AB19,$V$2:$V$1001,V993) -> 1122773.1 | AD19: =SUMIFS($H$2:$H$1001,$Y$2:$Y$1001,AB19,$V$2:$V$1001,V997) -> 1122773.1 | AE19: =SUMIFS($H$2:$H$1001,$Y$2:$Y$1001,AB19,$V$2:$V$1001,V10) -> 1435955.9
A20: ORD0019 | B20: Adam Mullins | C20: Printer | D20: Office Supplies | E20: South | F20: 8 | G20: 1560.78 | H20: 12486.24 | I20: 9150.61 | J20: 3335.63 | K20: 46104 | L20: 46112 | M20: Fathima | N20: 3 | O20: 08:53:00 | P20: 7 | Q20: =RIGHT(A20,"4") -> 0019 | R20: =IF('RETAIL SALES DATA.'!H20>AVERAGE('RETAIL SALES DATA.'!H20:H1019),"HIGHEST VALUE","LOWEST VALUE") -> LOWEST VALUE | S20: =IF(J20>0,"Profit","Loss") -> Profit | T20: =PROPER(B20) -> Adam Mullins | U20: =PROPER(C20) -> Printer | V20: =YEAR(K20) -> 2026 | W20: =MONTH(L20) -> 3 | X20: =DAY(K20) -> 23 | Y20: =TEXT(K20,"MMM") -> Mar | Z20: =L20-K20 -> 8 | AB20: Sep | AC20: =SUMIFS($H$2:$H$1001,$Y$2:$Y$1001,AB20,$V$2:$V$1001,V994) -> 1045399.3 | AD20: =SUMIFS($H$2:$H$1001,$Y$2:$Y$1001,AB20,$V$2:$V$1001,V998) -> 1045399.3 | AE20: =SUMIFS($H$2:$H$1001,$Y$2:$Y$1001,AB20,$V$2:$V$1001,V11) -> 1045399.3
A21: ORD0020 | B21: Sean Rodriguez | C21: Chair | D21: Furniture | E21: East | F21: 7 | G21: 581.16 | H21: 4068.12 | I21: 2668.67 | J21: 1399.45 | K21: 45805 | L21: 45814 | M21: Akhil | N21: 4 | O21: 11:20:00 | P21: 8.1 | Q21: =RIGHT(A21,"4") -> 0020 | R21: =IF('RETAIL SALES DATA.'!H21>AVERAGE('RETAIL SALES DATA.'!H21:H1020),"HIGHEST VALUE","LOWEST VALUE") -> LOWEST VALUE | S21: =IF(J21>0,"Profit","Loss") -> Profit | T21: =PROPER(B21) -> Sean Rodriguez | U21: =PROPER(C21) -> Chair | V21: =YEAR(K21) -> 2025 | W21: =MONTH(L21) -> 6 | X21: =DAY(K21) -> 28 | Y21: =TEXT(K21,"MMM") -> May | Z21: =L21-K21 -> 9 | AB21: Oct | AC21: =SUMIFS($H$2:$H$1001,$Y$2:$Y$1001,AB21,$V$2:$V$1001,V995) -> 0 | AD21: =SUMIFS($H$2:$H$1001,$Y$2:$Y$1001,AB21,$V$2:$V$1001,V999) -> 1137093.4 | AE21: =SUMIFS($H$2:$H$1001,$Y$2:$Y$1001,AB21,$V$2:$V$1001,V12) -> 1301211.4
A22: ORD0021 | B22: Joseph Mora | C22: Laptop | D22: Electronics | E22: East | F22: 16 | G22: 3094.38 | H22: 49510.08 | I22: 33974.06 | J22: 15536.02 | K22: 45623 | L22: 45626 | M22: Megha | N22: 1 | O22: 10:52:00 | P22: 6.7 | Q22: =RIGHT(A22,"4") -> 0021 | R22: =IF('RETAIL SALES DATA.'!H22>AVERAGE('RETAIL SALES DATA.'!H22:H1021),"HIGHEST VALUE","LOWEST VALUE") -> HIGHEST VALUE | S22: =IF(J22>0,"Profit","Loss") -> Profit | T22: =PROPER(B22) -> Joseph Mora | U22: =PROPER(C22) -> Laptop | V22: =YEAR(K22) -> 2024 | W22: =MONTH(L22) -> 11 | X22: =DAY(K22) -> 27 | Y22: =TEXT(K22,"MMM") -> Nov | Z22: =L22-K22 -> 3 | AB22: Nov | AC22: =SUMIFS($H$2:$H$1001,$Y$2:$Y$1001,AB22,$V$2:$V$1001,V996) -> 1086755.5 | AD22: =SUMIFS($H$2:$H$1001,$Y$2:$Y$1001,AB22,$V$2:$V$1001,V1000) -> 0 | AE22: =SUMIFS($H$2:$H$1001,$Y$2:$Y$1001,AB22,$V$2:$V$1001,V13) -> 1086755.5
A23: ORD0022 | B23: Deborah Hernandez | C23: Cupboard | D23: Furniture | E23: East | F23: 17 | G23: 4018.59 | H23: 68316.03 | I23: 51272.8 | J23: 17043.23 | K23: 46092 | L23: 46101 | M23: Diya | N23: 5 | O23: 09:23:00 | P23: 7.1 | Q23: =RIGHT(A23,"4") -> 0022 | R23: =IF('RETAIL SALES DATA.'!H23>AVERAGE('RETAIL SALES DATA.'!H23:H1022),"HIGHEST VALUE","LOWEST VALUE") -> HIGHEST VALUE | S23: =IF(J23>0,"Profit","Loss") -> Profit | T23: =PROPER(B23) -> Deborah Hernandez | U23: =PROPER(C23) -> Cupboard | V23: =YEAR(K23) -> 2026 | W23: =MONTH(L23) -> 3 | X23: =DAY(K23) -> 11 | Y23: =TEXT(K23,"MMM") -> Mar | Z23: =L23-K23 -> 9 | AB23: Dec | AC23: =SUMIFS($H$2:$H$1001,$Y$2:$Y$1001,AB23,$V$2:$V$1001,V997) -> 1027155.3 | AD23: =SUMIFS($H$2:$H$1001,$Y$2:$Y$1001,AB23,$V$2:$V$1001,V1001) -> 1027155.3 | AE23: =SUMIFS($H$2:$H$1001,$Y$2:$Y$1001,AB23,$V$2:$V$1001,V14) -> 1027155.3
A24: ORD0023 | B24: Elizabeth Moore | C24: Printer | D24: Office Supplies | E24: North | F24: 6 | G24: 3184.36 | H24: 19106.16 | I24: 10404.21 | J24: 8701.95 | K24: 45826 | L24: 45832 | M24: Sneha | N24: 5 | O24: 11:43:00 | P24: 6.3 | Q24: =RIGHT(A24,"4") -> 0023 | R24: =IF('RETAIL SALES DATA.'!H24>AVERAGE('RETAIL SALES DATA.'!H24:H1023),"HIGHEST VALUE","LOWEST VALUE") -> LOWEST VALUE | S24: =IF(J24>0,"Profit","Loss") -> Profit | T24: =PROPER(B24) -> Elizabeth Moore | U24: =PROPER(C24) -> Printer | V24: =YEAR(K24) -> 2025 | W24: =MONTH(L24) -> 6 | X24: =DAY(K24) -> 18 | Y24: =TEXT(K24,"MMM") -> Jun | Z24: =L24-K24 -> 6
A25: ORD0024 | B25: Melissa Davis | C25: Desk | D25: Furniture | E25: North | F25: 20 | G25: 267.78 | H25: 5355.6 | I25: 2790.07 | J25: 2565.53 | K25: 45603 | L25: 45613 | M25: Megha | N25: 5 | O25: 11:42:00 | P25: 7.6 | Q25: =RIGHT(A25,"4") -> 0024 | R25: =IF('RETAIL SALES DATA.'!H25>AVERAGE('RETAIL SALES DATA.'!H25:H1024),"HIGHEST VALUE","LOWEST VALUE") -> LOWEST VALUE | S25: =IF(J25>0,"Profit","Loss") -> Profit | T25: =PROPER(B25) -> Melissa Davis | U25: =PROPER(C25) -> Desk | V25: =YEAR(K25) -> 2024 | W25: =MONTH(L25) -> 11 | X25: =DAY(K25) -> 7 | Y25: =TEXT(K25,"MMM") -> Nov | Z25: =L25-K25 -> 10
A26: ORD0025 | B26: Andrew Gould | C26: Chair | D26: Furniture | E26: South | F26: 18 | G26: 1973.33 | H26: 35519.94 | I26: 18379.63 | J26: 17140.31 | K26: 45520 | L26: 45521 | M26: Fathima | N26: 3 | O26: 10:39:00 | P26: 8.3 | Q26: =RIGHT(A26,"4") -> 0025 | R26: =IF('RETAIL SALES DATA.'!H26>AVERAGE('RETAIL SALES DATA.'!H26:H1025),"HIGHEST VALUE","LOWEST VALUE") -> HIGHEST VALUE | S26: =IF(J26>0,"Profit","Loss") -> Profit | T26: =PROPER(B26) -> Andrew Gould | U26: =PROPER(C26) -> Chair | V26: =YEAR(K26) -> 2024 | W26: =MONTH(L26) -> 8 | X26: =DAY(K26) -> 16 | Y26: =TEXT(K26,"MMM") -> Aug | Z26: =L26-K26 -> 1
A27: ORD0026 | B27: Glen Scott | C27: Pen | D27: Office Supplies | E27: North | F27: 10 | G27: 4872.29 | H27: 48722.9 | I27: 30720.08 | J27: 18002.82 | K27: 45807 | L27: 45814 | M27: Akhil | N27: 3 | O27: 10:07:00 | P27: 6.8 | Q27: =RIGHT(A27,"4") -> 0026 | R27: =IF('RETAIL SALES DATA.'!H27>AVERAGE('RETAIL SALES DATA.'!H27:H1026),"HIGHEST VALUE","LOWEST VALUE") -> HIGHEST VALUE | S27: =IF(J27>0,"Profit","Loss") -> Profit | T27: =PROPER(B27) -> Glen Scott | U27: =PROPER(C27) -> Pen | V27: =YEAR(K27) -> 2025 | W27: =MONTH(L27) -> 6 | X27: =DAY(K27) -> 30 | Y27: =TEXT(K27,"MMM") -> May | Z27: =L27-K27 -> 7
A28: ORD0027 | B28: Isaac Fisher | C28: Notebook | D28: Office Supplies | E28: West | F28: 12 | G28: 3399.13 | H28: 40789.56 | I28: 26160.75 | J28: 14628.81 | K28: 45643 | L28: 45645 | M28: Diya | N28: 3 | O28: 10:46:00 | P28: 6.9 | Q28: =RIGHT(A28,"4") -> 0027 | R28: =IF('RETAIL SALES DATA.'!H28>AVERAGE('RETAIL SALES DATA.'!H28:H1027),"HIGHEST VALUE","LOWEST VALUE") -> HIGHEST VALUE | S28: =IF(J28>0,"Profit","Loss") -> Profit | T28: =PROPER(B28) -> Isaac Fisher | U28: =PROPER(C28) -> Notebook | V28: =YEAR(K28) -> 2024 | W28: =MONTH(L28) -> 12 | X28: =DAY(K28) -> 17 | Y28: =TEXT(K28,"MMM") -> Dec | Z28: =L28-K28 -> 2
A29: ORD0028 | B29: Matthew Hanson | C29: Laptop | D29: Electronics | E29: East | F29: 19 | G29: 352.92 | H29: 6705.48 | I29: 3564.37 | J29: 3141.11 | K29: 45666 | L29: 45675 | M29: Nikhil | N29: 2 | O29: 08:32:00 | P29: 8.5 | Q29: =RIGHT(A29,"4") -> 0028 | R29: =IF('RETAIL SALES DATA.'!H29>AVERAGE('RETAIL SALES DATA.'!H29:H1028),"HIGHEST VALUE","LOWEST VALUE") -> LOWEST VALUE | S29: =IF(J29>0,"Profit","Loss") -> Profit | T29: =PROPER(B29) -> Matthew Hanson | U29: =PROPER(C29) -> Laptop | V29: =YEAR(K29) -> 2025 | W29: =MONTH(L29) -> 1 | X29: =DAY(K29) -> 9 | Y29: =TEXT(K29,"MMM") -> Jan | Z29: =L29-K29 -> 9
A30: ORD0029 | B30: Jamie Benton | C30: Notebook | D30: Office Supplies | E30: West | F30: 18 | G30: 1397.43 | H30: 25153.74 | I30: 16703.28 | J30: 8450.46 | K30: 45843 | L30: 45846 | M30: Megha | N30: 2 | O30: 10:55:00 | P30: 8.9 | Q30: =RIGHT(A30,"4") -> 0029 | R30: =IF('RETAIL SALES DATA.'!H30>AVERAGE('RETAIL SALES DATA.'!H30:H1029),"HIGHEST VALUE","LOWEST VALUE") -> LOWEST VALUE | S30: =IF(J30>0,"Profit","Loss") -> Profit | T30: =PROPER(B30) -> Jamie Benton | U30: =PROPER(C30) -> Notebook | V30: =YEAR(K30) -> 2025 | W30: =MONTH(L30) -> 7 | X30: =DAY(K30) -> 5 | Y30: =TEXT(K30,"MMM") -> Jul | Z30: =L30-K30 -> 3
A31: ORD0030 | B31: Kristy Sullivan | C31: Pen | D31: Office Supplies | E31: South | F31: 17 | G31: 4186.24 | H31: 71166.08 | I31: 58945.05 | J31: 12221.03 | K31: 45813 | L31: 45819 | M31: Fathima | N31: 4 | O31: 10:42:00 | P31: 6.3 | Q31: =RIGHT(A31,"4") -> 0030 | R31: =IF('RETAIL SALES DATA.'!H31>AVERAGE('RETAIL SALES DATA.'!H31:H1030),"HIGHEST VALUE","LOWEST VALUE") -> HIGHEST VALUE | S31: =IF(J31>0,"Profit","Loss") -> Profit | T31: =PROPER(B31) -> Kristy Sullivan | U31: =PROPER(C31) -> Pen | V31: =YEAR(K31) -> 2025 | W31: =MONTH(L31) -> 6 | X31: =DAY(K31) -> 5 | Y31: =TEXT(K31,"MMM") -> Jun | Z31: =L31-K31 -> 6 | AC31: MAXIMUM DELIVERY DAYS | AD31: =MAX(Table13[DELIVERY DATE]) -> 10
A32: ORD0031 | B32: Carolyn Scott | C32: Pen | D32: Office Supplies | E32: West | F32: 1 | G32: 2612.03 | H32: 2612.03 | I32: 1575.12 | J32: 1036.91 | K32: 45480 | L32: 45485 | M32: Vivek | N32: 3 | O32: 10:01:00 | P32: 6.5 | Q32: =RIGHT(A32,"4") -> 0031 | R32: =IF('RETAIL SALES DATA.'!H32>AVERAGE('RETAIL SALES DATA.'!H32:H1031),"HIGHEST VALUE","LOWEST VALUE") -> LOWEST VALUE | S32: =IF(J32>0,"Profit","Loss") -> Profit | T32: =PROPER(B32) -> Carolyn Scott | U32: =PROPER(C32) -> Pen | V32: =YEAR(K32) -> 2024 | W32: =MONTH(L32) -> 7 | X32: =DAY(K32) -> 7 | Y32: =TEXT(K32,"MMM") -> Jul | Z32: =L32-K32 -> 5 | AC32: MINIMUM DELIVERY DAYS | AD32: =MIN(Table13[DELIVERY DATE]) -> 1
A33: ORD0032 | B33: Mary Day | C33: Chair | D33: Furniture | E33: West | F33: 13 | G33: 3740.17 | H33: 48622.21 | I33: 41341.16 | J33: 7281.05 | K33: 45808 | L33: 45812 | M33: Rahul | N33: 3 | O33: 08:27:00 | P33: 6.3 | Q33: =RIGHT(A33,"4") -> 0032 | R33: =IF('RETAIL SALES DATA.'!H33>AVERAGE('RETAIL SALES DATA.'!H33:H1032),"HIGHEST VALUE","LOWEST VALUE") -> HIGHEST VALUE | S33: =IF(J33>0,"Profit","Loss") -> Profit | T33: =PROPER(B33) -> Mary Day | U33: =PROPER(C33) -> Chair | V33: =YEAR(K33) -> 2025 | W33: =MONTH(L33) -> 6 | X33: =DAY(K33) -> 31 | Y33: =TEXT(K33,"MMM") -> May | Z33: =L33-K33 -> 4 | AI33: MONTHS
A34: ORD0033 | B34: Matthew Fernandez | C34: Sofa | D34: Furniture | E34: East | F34: 12 | G34: 3480.93 | H34: 41771.16 | I34: 23955 | J34: 17816.16 | K34: 46026 | L34: 46032 | M34: Rahul | N34: 2 | O34: 11:34:00 | P34: 7 | Q34: =RIGHT(A34,"4") -> 0033 | R34: =IF('RETAIL SALES DATA.'!H34>AVERAGE('RETAIL SALES DATA.'!H34:H1033),"HIGHEST VALUE","LOWEST VALUE") -> HIGHEST VALUE | S34: =IF(J34>0,"Profit","Loss") -> Profit | T34: =PROPER(B34) -> Matthew Fernandez | U34: =PROPER(C34) -> Sofa | V34: =YEAR(K34) -> 2026 | W34: =MONTH(L34) -> 1 | X34: =DAY(K34) -> 4 | Y34: =TEXT(K34,"MMM") -> Jan | Z34: =L34-K34 -> 6 | AI34: Jan
A35: ORD0034 | B35: Tonya Gallegos | C35: Printer | D35: Office Supplies | E35: West | F35: 18 | G35: 4419.1 | H35: 79543.8 | I35: 47654.84 | J35: 31888.96 | K35: 45629 | L35: 45639 | M35: Fathima | N35: 4 | O35: 10:16:00 | P35: 7.7 | Q35: =RIGHT(A35,"4") -> 0034 | R35: =IF('RETAIL SALES DATA.'!H35>AVERAGE('RETAIL SALES DATA.'!H35:H1034),"HIGHEST VALUE","LOWEST VALUE") -> HIGHEST VALUE | S35: =IF(J35>0,"Profit","Loss") -> Profit | T35: =PROPER(B35) -> Tonya Gallegos | U35: =PROPER(C35) -> Printer | V35: =YEAR(K35) -> 2024 | W35: =MONTH(L35) -> 12 | X35: =DAY(K35) -> 3 | Y35: =TEXT(K35,"MMM") -> Dec | Z35: =L35-K35 -> 10 | AI35: Feb
A36: ORD0035 | B36: Jody Black | C36: File | D36: Office Supplies | E36: South | F36: 10 | G36: 4243.55 | H36: 42435.5 | I36: 29127.76 | J36: 13307.74 | K36: 45916 | L36: 45925 | M36: Akhil | N36: 2 | O36: 11:25:00 | P36: 9.4 | Q36: =RIGHT(A36,"4") -> 0035 | R36: =IF('RETAIL SALES DATA.'!H36>AVERAGE('RETAIL SALES DATA.'!H36:H1035),"HIGHEST VALUE","LOWEST VALUE") -> HIGHEST VALUE | S36: =IF(J36>0,"Profit","Loss") -> Profit | T36: =PROPER(B36) -> Jody Black | U36: =PROPER(C36) -> File | V36: =YEAR(K36) -> 2025 | W36: =MONTH(L36) -> 9 | X36: =DAY(K36) -> 16 | Y36: =TEXT(K36,"MMM") -> Sep | Z36: =L36-K36 -> 9 | AI36: Mar
A37: ORD0036 | B37: Laurie Flores | C37: File | D37: Office Supplies | E37: East | F37: 16 | G37: 2535.18 | H37: 40562.88 | I37: 31992.98 | J37: 8569.9 | K37: 46117 | L37: 46121 | M37: Diya | N37: 2 | O37: 11:39:00 | P37: 9.4 | Q37: =RIGHT(A37,"4") -> 0036 | R37: =IF('RETAIL SALES DATA.'!H37>AVERAGE('RETAIL SALES DATA.'!H37:H1036),"HIGHEST VALUE","LOWEST VALUE") -> HIGHEST VALUE | S37: =IF(J37>0,"Profit","Loss") -> Profit | T37: =PROPER(B37) -> Laurie Flores | U37: =PROPER(C37) -> File | V37: =YEAR(K37) -> 2026 | W37: =MONTH(L37) -> 4 | X37: =DAY(K37) -> 5 | Y37: =TEXT(K37,"MMM") -> Apr | Z37: =L37-K37 -> 4 | AC37: =SUMIF(Table13[YEAR],V987,H2:H1001) -> 13413606 | AI37: Apr
A38: ORD0037 | B38: Charles Logan | C38: Mouse | D38: Electronics | E38: West | F38: 10 | G38: 2467.57 | H38: 24675.7 | I38: 16242.09 | J38: 8433.61 | K38: 45913 | L38: 45917 | M38: Rahul | N38: 3 | O38: 08:56:00 | P38: 6.1 | Q38: =RIGHT(A38,"4") -> 0037 | R38: =IF('RETAIL SALES DATA.'!H38>AVERAGE('RETAIL SALES DATA.'!H38:H1037),"HIGHEST VALUE","LOWEST VALUE") -> LOWEST VALUE | S38: =IF(J38>0,"Profit","Loss") -> Profit | T38: =PROPER(B38) -> Charles Logan | U38: =PROPER(C38) -> Mouse | V38: =YEAR(K38) -> 2025 | W38: =MONTH(L38) -> 9 | X38: =DAY(K38) -> 13 | Y38: =TEXT(K38,"MMM") -> Sep | Z38: =L38-K38 -> 4 | AI38: May
A39: ORD0038 | B39: Lori Petersen | C39: Sofa | D39: Furniture | E39: South | F39: 7 | G39: 3511.87 | H39: 24583.09 | I39: 14650.99 | J39: 9932.1 | K39: 45726 | L39: 45728 | M39: Rahul | N39: 5 | O39: 09:54:00 | P39: 7.5 | Q39: =RIGHT(A39,"4") -> 0038 | R39: =IF('RETAIL SALES DATA.'!H39>AVERAGE('RETAIL SALES DATA.'!H39:H1038),"HIGHEST VALUE","LOWEST VALUE") -> LOWEST VALUE | S39: =IF(J39>0,"Profit","Loss") -> Profit | T39: =PROPER(B39) -> Lori Petersen | U39: =PROPER(C39) -> Sofa | V39: =YEAR(K39) -> 2025 | W39: =MONTH(L39) -> 3 | X39: =DAY(K39) -> 10 | Y39: =TEXT(K39,"MMM") -> Mar | Z39: =L39-K39 -> 2 | AI39: Jun
A40: ORD0039 | B40: Roger Gutierrez | C40: Chair | D40: Furniture | E40: North | F40: 3 | G40: 2167.58 | H40: 6502.74 | I40: 5214.81 | J40: 1287.93 | K40: 45752 | L40: 45761 | M40: Fathima | N40: 5 | O40: 09:13:00 | P40: 8.4 | Q40: =RIGHT(A40,"4") -> 0039 | R40: =IF('RETAIL SALES DATA.'!H40>AVERAGE('RETAIL SALES DATA.'!H40:H1039),"HIGHEST VALUE","LOWEST VALUE") -> LOWEST VALUE | S40: =IF(J40>0,"Profit","Loss") -> Profit | T40: =PROPER(B40) -> Roger Gutierrez | U40: =PROPER(C40) -> Chair | V40: =YEAR(K40) -> 2025 | W40: =MONTH(L40) -> 4 | X40: =DAY(K40) -> 5 | Y40: =TEXT(K40,"MMM") -> Apr | Z40: =L40-K40 -> 9 | AI40: Jul
...

Sheet Sheet1
A1: BEST SELLING PRODUCT | B1: QUANTITY | C1: PRODUCT
B2: =SUMIFS('RETAIL SALES DATA.'!F2:F1001,'RETAIL SALES DATA.'!C2:C1001,C2) -> 633 | C2: {=_xlfn.UNIQUE('RETAIL SALES DATA.'!C2:C1001)} -> Pen
B3: =SUMIFS('RETAIL SALES DATA.'!F3:F1002,'RETAIL SALES DATA.'!C3:C1002,C3) -> 859 | C3: Desk | D3: BEST SELLING
B4: =SUMIFS('RETAIL SALES DATA.'!F4:F1003,'RETAIL SALES DATA.'!C4:C1003,C4) -> 590 | C4: Marker | D4: LEAST SELLING | I4: Total Sales | J4: =SUM('RETAIL SALES DATA.'!H2:H1001) -> 26471144
B5: =SUMIFS('RETAIL SALES DATA.'!F5:F1004,'RETAIL SALES DATA.'!C5:C1004,C5) -> 691 | C5: Laptop | I5: Total profit | J5: =SUM('RETAIL SALES DATA.'!J2:J1001) -> 8204131.4
B6: =SUMIFS('RETAIL SALES DATA.'!F6:F1005,'RETAIL SALES DATA.'!C6:C1005,C6) -> 747 | C6: Mouse | I6: Total Quantitysold | J6: =SUM('RETAIL SALES DATA.'!F2:F1001) -> 10506
B7: =SUMIFS('RETAIL SALES DATA.'!F7:F1006,'RETAIL SALES DATA.'!C7:C1006,C7) -> 635 | C7: Notebook
B8: =SUMIFS('RETAIL SALES DATA.'!F8:F1007,'RETAIL SALES DATA.'!C8:C1007,C8) -> 688 | C8: Table
B9: =SUMIFS('RETAIL SALES DATA.'!F9:F1008,'RETAIL SALES DATA.'!C9:C1008,C9) -> 768 | C9: Chair
B10: =SUMIFS('RETAIL SALES DATA.'!F10:F1009,'RETAIL SALES DATA.'!C10:C1009,C10) -> 672 | C10: Cupboard
B11: =SUMIFS('RETAIL SALES DATA.'!F11:F1010,'RETAIL SALES DATA.'!C11:C1010,C11) -> 832 | C11: Printer
B12: =SUMIFS('RETAIL SALES DATA.'!F12:F1011,'RETAIL SALES DATA.'!C12:C1011,C12) -> 693 | C12: Sofa
B13: =SUMIFS('RETAIL SALES DATA.'!F13:F1012,'RETAIL SALES DATA.'!C13:C1012,C13) -> 767 | C13: File
B14: =SUMIFS('RETAIL SALES DATA.'!F14:F1013,'RETAIL SALES DATA.'!C14:C1013,C14) -> 671 | C14: Keyboard
B15: =SUMIFS('RETAIL SALES DATA.'!F15:F1014,'RETAIL SALES DATA.'!C15:C1014,C15) -> 657 | C15: Monitor
B16: =SUMIFS('RETAIL SALES DATA.'!F16:F1015,'RETAIL SALES DATA.'!C16:C1015,C16) -> 603 | C16: Smartphone
A18: SALES&PROFIT
B19: CATEGORY | C19: HIGH | D19: LOW
B20: SALES | C20: =MAX('RETAIL SALES DATA.'!H2:H1001) -> 96471.6 | D20: =MIN('RETAIL SALES DATA.'!H2:H1001) -> 84.04
B21: PROFIT | C21: =MAX('RETAIL SALES DATA.'!J2:J1001) -> 41219.44 | D21: =MIN('RETAIL SALES DATA.'!J2:J1001) -> 10.48
A24: AVDERAGE SALES AND PROFIT
B27: AVERAGE PROFIT | C27: AVERAGE SALES
B28: =AVERAGE('RETAIL SALES DATA.'!J2:J1001) -> 8204.1314 | C28: =AVERAGE('RETAIL SALES DATA.'!H2:H1001) -> 26471.144
A30: REGION GENERATED HIGHEST VALUE
B33: {=_xlfn.UNIQUE('RETAIL SALES DATA.'!E2:E1001)} -> South | C33: =SUMIF('RETAIL SALES DATA.'!E2:E1001,B33,'RETAIL SALES DATA.'!H2:H1001) -> 5968196.4
B34: North | C34: =SUMIF('RETAIL SALES DATA.'!E3:E1002,B34,'RETAIL SALES DATA.'!H3:H1002) -> 6653980.9
B35: West | C35: =SUMIF('RETAIL SALES DATA.'!E4:E1003,B35,'RETAIL SALES DATA.'!H4:H1003) -> 7688782.6 | D35: GENERATED HIGHEST VALUE
B36: East | C36: =SUMIF('RETAIL SALES DATA.'!E5:E1004,B36,'RETAIL SALES DATA.'!H5:H1004) -> 6160183.7
A38: NUMBERS OF ORDERS FROM EACH REGION
B41: {=_xlfn.UNIQUE('RETAIL SALES DATA.'!E2:E1001)} -> South | C41: =COUNTIF('RETAIL SALES DATA.'!E2:E1001,B41) -> 230
B42: North | C42: =COUNTIF('RETAIL SALES DATA.'!E3:E1002,B42) -> 251
B43: West | C43: =COUNTIF('RETAIL SALES DATA.'!E4:E1003,B43) -> 282
B44: East | C44: =COUNTIF('RETAIL SALES DATA.'!E5:E1004,B44) -> 237
A47: SALES FOR EACH CATEGORY
B48: {=_xlfn.UNIQUE('RETAIL SALES DATA.'!E17:E1016)} -> West | C48: =SUMIF('RETAIL SALES DATA.'!E17:E1016,B48,'RETAIL SALES DATA.'!H17:H1016) -> 7566871.8
B49: North | C49: =SUMIF('RETAIL SALES DATA.'!E18:E1017,B49,'RETAIL SALES DATA.'!H18:H1017) -> 6582015.8
B50: South | C50: =SUMIF('RETAIL SALES DATA.'!E19:E1018,B50,'RETAIL SALES DATA.'!H19:H1018) -> 5909004.6
B51: East | C51: =SUMIF('RETAIL SALES DATA.'!E20:E1019,B51,'RETAIL SALES DATA.'!H20:H1019) -> 6062618.1
B52: 0
A53: CLASSIFY TRANSACTION
...
